<?xml version="1.0" ?>
<!-- =================================================================================== -->
<!-- |    This document was autogenerated by xacro from holonomic_mm_no_arm.urdf.xacro | -->
<!-- |    EDITING THIS FILE BY HAND IS NOT RECOMMENDED                                 | -->
<!-- =================================================================================== -->
<robot name="holonomic_base">
  <!-- "" -->
  <link name="base_link">
    <inertial>
      <origin rpy="0 0 0" xyz="-0.0107573806983678 -0.000121111379146382 0.168820068401291"/>
      <mass value="30.0"/>
      <inertia ixx="0.674364406464489" ixy="2.6530001859869E-06" ixz="-2.02885454828053E-06" iyy="0.607129183001536" iyz="-2.82546028667119E-08" izz="0.67886359812438"/>
    </inertial>
    <visual>
      <origin rpy="0 0 0" xyz="0 0 0"/>
      <geometry>
        <mesh filename="./meshes/holonomic/base_link.STL"/>
      </geometry>
      <material name="">
        <color rgba="0.752941176470588 0.752941176470588 0.752941176470588 1"/>
      </material>
    </visual>
    <collision>
      <origin rpy="0 0 0" xyz="0 0 0"/>
      <geometry>
        <mesh filename="./meshes/holonomic/base_link.STL"/>
      </geometry>
    </collision>
  </link>

  
  <link name="leg_fl">
    <inertial>
      <origin rpy="0 0 0" xyz="0.0 0.0 -0.041346"/>
      <mass value="1.0"/>
      <inertia ixx="8.621E-03" ixy="-2.6953E-09" ixz="-8.1387E-10" iyy="5.4519E-03" iyz="-1.5042E-09" izz="6.6419E-03"/>
    </inertial>
    <visual>
      <origin rpy="0 0 0" xyz="0 0 0"/>
      <geometry>
        <mesh filename="./meshes/holonomic/turn_front_left_link.STL"/>
      </geometry>
      <material name="">
        <color rgba="0.75294 0.75294 0.75294 1"/>
      </material>
    </visual>
    <collision>
      <origin rpy="0 0 0" xyz="0 0 0"/>
      <geometry>
        <mesh filename="./meshes/holonomic/turn_front_left_link.STL"/>
      </geometry>
    </collision>
  </link>
  <joint name="left_front_steer_joint" type="revolute">
    <origin rpy="3.1415926 0 3.1415926" xyz="0.285 0.215 0.0705"/>
    <parent link="base_link"/>
    <child link="leg_fl"/>
    <axis xyz="0 0 1"/>
    <limit effort="1000.0" lower="-3.341" upper="3.341" velocity="5.00"/>
    <joint_properties damping="1.0"/>
  </joint>
  <link name="leg_fr">
    <inertial>
      <origin rpy="0 0 0" xyz="0.0 0.0 -0.041346"/>
      <mass value="1.0"/>
      <inertia ixx="8.621E-03" ixy="-2.6953E-09" ixz="-8.1387E-10" iyy="5.4519E-03" iyz="-1.5042E-09" izz="6.6419E-03"/>
    </inertial>
    <visual>
      <origin rpy="0 0 0" xyz="0 0 0"/>
      <geometry>
        <mesh filename="./meshes/holonomic/turn_front_right_link.STL"/>
      </geometry>
      <material name="">
        <color rgba="0.75294 0.75294 0.75294 1"/>
      </material>
    </visual>
    <collision>
      <origin rpy="0 0 0" xyz="0 0 0"/>
      <geometry>
        <mesh filename="./meshes/holonomic/turn_front_right_link.STL"/>
      </geometry>
    </collision>
  </link>
  <joint name="right_front_steer_joint" type="revolute">
    <origin rpy="3.1415926 0 3.1415926" xyz="0.285 -0.215 0.0705"/>
    <!-- <origin xyz="0.585 -0.215 0.0705" rpy="3.14159265358979 0 3.14159265358979" /> -->
    <parent link="base_link"/>
    <child link="leg_fr"/>
    <axis xyz="0 0 1"/>
    <limit effort="1000.0" lower="-3.341" upper="3.341" velocity="5.00"/>
    <joint_properties damping="1.0"/>
  </joint>

  <link name="leg_rl">
    <inertial>
      <origin rpy="0 0 0" xyz="0.0 0.0 -0.041346"/>
      <mass value="1.0"/>
      <inertia ixx="8.621E-03" ixy="-2.6953E-09" ixz="-8.1387E-10" iyy="5.4519E-03" iyz="-1.5042E-09" izz="6.6419E-03"/>
    </inertial>
    <visual>
      <origin rpy="0 0 0" xyz="0 0 0"/>
      <geometry>
        <mesh filename="./meshes/holonomic/turn_back_left_link.STL"/>
      </geometry>
      <material name="">
        <color rgba="0.75294 0.75294 0.75294 1"/>
      </material>
    </visual>
    <collision>
      <origin rpy="0 0 0" xyz="0 0 0"/>
      <geometry>
        <mesh filename="./meshes/holonomic/turn_back_left_link.STL"/>
      </geometry>
    </collision>
  </link>
  <joint name="left_back_steer_joint" type="revolute">
    <origin rpy="-3.1415926 0 0" xyz="-0.285 0.215 0.0705"/>
    <!-- <origin xyz="-0.585 0.215 0.0705" rpy="-3.141592653 0 0" /> -->
    <parent link="base_link"/>
    <child link="leg_rl"/>
    <axis xyz="0 0 1"/>
    <limit effort="1000.0" lower="-3.341" upper="3.341" velocity="5.00"/>
    <joint_properties damping="1.0"/>
  </joint>

  <link name="leg_rr">
    <inertial>
      <origin rpy="0 0 0" xyz="0.0 0.0 -0.041346"/>
      <mass value="1.0"/>
      <inertia ixx="8.621E-03" ixy="-2.6953E-09" ixz="-8.1387E-10" iyy="5.4519E-03" iyz="-1.5042E-09" izz="6.6419E-03"/>
    </inertial>
    <visual>
      <origin rpy="0 0 0" xyz="0 0 0"/>
      <geometry>
        <mesh filename="./meshes/holonomic/turn_back_right_link.STL"/>
      </geometry>
      <material name="">
        <color rgba="0.75294 0.75294 0.75294 1"/>
      </material>
    </visual>
    <collision>
      <origin rpy="0 0 0" xyz="0 0 0"/>
      <geometry>
        <mesh filename="./meshes/holonomic/turn_back_right_link.STL"/>
      </geometry>
    </collision>
  </link>
  <joint name="right_back_steer_joint" type="revolute">
    <origin rpy="3.1415926 0 0" xyz="-0.285 -0.215 0.0705"/>
    <!-- <origin xyz="-0.585 -0.215 0.0705" rpy="3.141592653 0 0" /> -->
    <parent link="base_link"/>
    <child link="leg_rr"/>
    <axis xyz="0 0 1"/>
    <limit effort="1000.0" lower="-3.341" upper="3.341" velocity="5.00"/>
    <joint_properties damping="1.0"/>
  </joint>

  <link name="wheel_fl">
    <inertial>
      <origin rpy="0 0 0" xyz="-6.7203E-07 -0.0039185 1.1995E-07"/>
      <mass value="3.1"/>
      <inertia ixx="8.621E-02" ixy="-2.6953E-09" ixz="-8.1387E-10" iyy="5.4519E-02" iyz="-1.5042E-09" izz="6.6419E-02"/>
    </inertial>
    <visual>
      <origin rpy="0 0 0" xyz="0 0 0"/>
      <geometry>
        <mesh filename="./meshes/holonomic/wheel_front_left_link.STL"/>
      </geometry>
      <material name="">
        <color rgba="1 0.75294 0.75294 1"/>
      </material>
    </visual>
    <collision>
      <origin rpy="0 0 0" xyz="0 0 0"/>
      <geometry>
        <mesh filename="./meshes/holonomic/wheel_front_left_link.STL"/>
      </geometry>
    </collision>
  </link>
  <joint name="left_front_wheel_joint" type="continuous">
    <origin rpy="-1.570796327 1.570796327 0" xyz="0 0.0039 0.101"/>
    <parent link="leg_fl"/>
    <child link="wheel_fl"/>
    <axis xyz="0 0 1"/>
    <limit effort="10000" velocity="100"/>
    <joint_properties damping="1.0"/>
  </joint>

  <link name="wheel_fr">
    <inertial>
      <origin rpy="0 0 0" xyz="6.7203E-07 0.0039185 1.1995E-07"/>
      <mass value="3.1"/>
      <inertia ixx="8.621E-02" ixy="-2.6953E-09" ixz="-8.1387E-10" iyy="5.4519E-02" iyz="-1.5042E-09" izz="6.6419E-02"/>
    </inertial>
    <visual>
      <origin rpy="0 0 0" xyz="0 0 0"/>
      <geometry>
        <mesh filename="./meshes/holonomic/wheel_front_right_link.STL"/>
      </geometry>
      <material name="">
        <color rgba="1 0.75294 0.75294 1"/>
      </material>
    </visual>
    <collision>
      <origin rpy="0 0 0" xyz="0 0 0"/>
      <geometry>
        <mesh filename="./meshes/holonomic/wheel_front_right_link.STL"/>
      </geometry>
    </collision>
  </link>
  <joint name="right_front_wheel_joint" type="continuous">
    <origin rpy="1.570796327 1.570796327 0" xyz="0 -0.0039 0.101"/>
    <parent link="leg_fr"/>
    <child link="wheel_fr"/>
    <axis xyz="0 0 1"/>
    <limit effort="10000" velocity="100"/>
    <joint_properties damping="1.0"/>
  </joint>

  <link name="wheel_rl">
    <inertial>
      <origin rpy="0 0 0" xyz="-6.7203E-07 -0.0039185 1.1995E-07"/>
      <mass value="3.1"/>
      <inertia ixx="8.621E-02" ixy="-2.6953E-09" ixz="-8.1387E-10" iyy="5.4519E-02" iyz="-1.5042E-09" izz="6.6419E-02"/>
    </inertial>
    <visual>
      <origin rpy="0 0 0" xyz="0 0 0"/>
      <geometry>
        <mesh filename="./meshes/holonomic/wheel_back_left_link.STL"/>
      </geometry>
      <material name="">
        <color rgba="1 0.75294 0.75294 1"/>
      </material>
    </visual>
    <collision>
      <origin rpy="0 0 0" xyz="0 0 0"/>
      <geometry>
        <mesh filename="./meshes/holonomic/wheel_back_left_link.STL"/>
      </geometry>
    </collision>
  </link>
  <joint name="left_back_wheel_joint" type="continuous">
    <origin rpy="1.570796327 1.570796327 0" xyz="0 -0.0039 0.101"/>
    <parent link="leg_rl"/>
    <child link="wheel_rl"/>
    <axis xyz="0 0 1"/>
    <limit effort="10000" velocity="100"/>
    <joint_properties damping="1.0"/>
  </joint>

  <link name="wheel_rr">
    <inertial>
      <origin rpy="0 0 0" xyz="6.7203E-07 0.0039185 1.1995E-07"/>
      <mass value="3.1"/>
      <inertia ixx="8.621E-02" ixy="-2.6953E-09" ixz="-8.1387E-10" iyy="5.4519E-02" iyz="-1.5042E-09" izz="6.6419E-02"/>
    </inertial>
    <visual>
      <origin rpy="0 0 0" xyz="0 0 0"/>
      <geometry>
        <mesh filename="./meshes/holonomic/wheel_back_right_link.STL"/>
      </geometry>
      <material name="">
        <color rgba="1 0.75294 0.75294 1"/>
      </material>
    </visual>
    <collision>
      <origin rpy="0 0 0" xyz="0 0 0"/>
      <geometry>
        <mesh filename="./meshes/holonomic/wheel_back_right_link.STL"/>
      </geometry>
    </collision>
  </link>
  <joint name="right_back_wheel_joint" type="continuous">
    <origin rpy="-1.570796327 1.570796327 0" xyz="0 0.0039 0.101"/>
    <parent link="leg_rr"/>
    <child link="wheel_rr"/>
    <axis xyz="0 0 1"/>
    <limit effort="10000" velocity="100"/>
    <joint_properties damping="1.0"/>
  </joint>
</robot>

